<!DOCTYPE html>
<html lang="en">
  <head>
    <meta charset="utf-8">
    <title> Error Handling </title>
    <link rel="stylesheet" href="https://use.fontawesome.com/releases/v5.3.1/css/all.css" integrity="sha384-mzrmE5qonljUremFsqc01SB46JvROS7bZs3IO2EmfFsd15uHvIt+Y8vEf7N7fWAU" crossorigin="anonymous">
    <script src="https://ajax.googleapis.com/ajax/libs/jquery/3.3.1/jquery.min.js"></script>
    <link rel="stylesheet" href="../../Assets/stylesPages.css">
    <script src="../../Assets/scriptPages.js"></script>
  </head>
  <body>
    <h1> Error Handling </h1>
    <p> Updated: ( 2017-12-12 / 2018-04-14 / 2019-02-08 / 2020-07-24 / 2025-03-03 )</p>
    <nav class="sitenav">
      <a href="../../index.html">MySite > </a>
      <a href="../index.html">JavaScript > </a> Error Handling
    </nav>
    <table class="table">
      <caption>
        Error Object
      </caption>
      <tr>
        <th style="width:30%;"> Object </th>
        <th> Description </th>
      </tr>
      <tr>
        <td> Error(<i>msg:str</i> <opt>{ cause: <optval>str</optval> }</opt>) </td>
        <td>
          - general error object <br>
          - <i class="fab fa-js">2022</i> <span id="browserSupport" title="updated: 2025-03-03">
            <span><i class="fab fa-chrome"></i> 93 </span>
            <span><i class="fab fa-firefox"></i> 91 </span>
            <span><i class="fab fa-opera"></i> 79 </span>
            <span><i class="fab fa-internet-explorer"></i><i class="fab fa-edge"></i> 93 </span>
            <span><i class="fab fa-safari"></i> 17.3 </span>
            <span><i class="fab fa-node-js"></i> 16.9 </span>
          </span> cause (useful when re-throwing error)
        </td>
      </tr>
      <tr>
        <td>|</td>
        <td></td>
      </tr>
      <tr>
        <td> <a href="https://developer.mozilla.org/en-US/docs/Web/JavaScript/Reference/Global_Objects/Error#error_types" target="_blank">OtherErrors</a> </td>
        <td>
          - syntax error (thrown when the code is syntactically invalid)
        </td>
      </tr>
      <tr>
        <td>|</td>
        <td></td>
      </tr>
      <tr>
        <td colspan="2"> Properties </td>
      </tr>
      <tr>
        <td> <strong>errorObj</strong>.message </td>
        <td>
          - returns the error's message as a string
        </td>
      </tr>
      <tr>
        <td> <strong>errorObj</strong>.name </td>
        <td>
          - returns the error object constructor's name as a string
        </td>
      </tr>
      <tr>
        <td> <strong>errorObj</strong>.cause </td>
        <td>
          - <i class="fab fa-js">2022</i> returns the error's cause
          <span id="browserSupport" title="updated: 2025-03-03">
            <span><i class="fab fa-chrome"></i> 93 </span>
            <span><i class="fab fa-firefox"></i> 91 </span>
            <span><i class="fab fa-opera"></i> 79 </span>
            <span><i class="fab fa-internet-explorer"></i><i class="fab fa-edge"></i> 93 </span>
            <span><i class="fab fa-safari"></i> 17.3 </span>
            <span><i class="fab fa-node-js"></i> 16.9 </span>
          </span>
        </td>
      </tr>
    </table>
    <h2 class="headerSection"> Notes : </h2>
    <details class="example" id="notes">
      <summary> Notes :</summary>
      <p> - not standart <mark>profile()</mark> and <mark>profileEnd()</mark> not tested [2019-02-09], it does some perfornace profile thing </p>
    </details>
    <h2 class="headerSection"> Useful Links : </h2>
    <p><a href="https://www.w3schools.com/js/js_errors.asp" target="_blank"> W3Schools JavaScript Errors </a></p>
    <h2 class="headerSection"> Remember This : </h2>

    <h2 class="headerSection"> Description and Demonstration : </h2>
    <p> - if JavaScript encounters and error creates the apropriate Error Object and throws it </p>
    <pre class="syntax">
    throw <strong>val</strong>         // throws a the passed value (<reqval>Err</reqval> object usually)
    
    debugger                          // invokes the debugging functionality of the host if any, otherwide do nothing
    </pre>
    <details class="example">
      <summary> DEMO </summary>
      <pre>
    throw Error('some error');        // throws custom error
    throw 'some string';              // throws a value 
    
  // cause ---------------
    try {
      throw Error('some error', { cause: 'testing' });
    } catch (err) {
      err.cause;                      // -> 'testing'
    }
    
    
// debugger ---------------------
    debugger;                        // in browser this invoces the debugger functionality
    </pre>
      <hr>
      <!------------------------------------------------------------------------>
      <h4 class="header"> The <mark>RangeError</mark> object </h4>
      <pre>
    var number = 14;
    
    try {                       
        number.toPrecision(500); 
    }
    catch(errorObject){
        errorObject.name                        // -> "RangeError"
        errorObject.message                     // -> "toPrecision() argument must be between 1 and 100"
    }
    </pre>
      <hr>
      <!------------------------------------------------------------------------>
      <h4 class="header"> The <mark>ReferenceError</mark> object </h4>
      <pre>
    try {
        cap;   
    }
    catch(errorObject){
        errorObject.name                        // -> "ReferenceError"
        errorObject.message                     // -> "cap is not defined"
    }
    </pre>
      <hr>
      <!------------------------------------------------------------------------>
      <h4 class="header"> The <mark>SyntaxError</mark> object </h4>
      <pre>
    try{
        eval("console{}")                       // <u>we use eval function here, otherwise the "try" statement cannot pass the exeption</u>
        console.{}                              // this would shut down all further code because of the SyntaxError
    }
    catch(errorObject){
        errorObject.name                        // -> "SyntaxError"
        errorObject.message                     // -> "Invalid or unexpected token {"
    }
    </pre>
      <hr>
      <!------------------------------------------------------------------------>
      <h4 class="header"> The <mark>TypeError</mark> object </h4>
      <pre>
    var one = true;
    try{
        one.getDate(); 
    }
    catch(errorObject){
        errorObject.name                        // -> "TypeError"
        errorObject.message                     // -> "one.getDate is not a function"
    }
    </pre>
      <hr>
      <!------------------------------------------------------------------------>
      <h4 class="header"> The <mark>URIError</mark> object </h4>
      <pre>
    try{
        decodeURI("%Â£$*&");          
    }
    catch(errorObject){
        errorObject.name                        // -> "URIError"
        errorObject.message                     // -> "URI malformed"
    }
    </pre>
      <hr>
      <!------------------------------------------------------------------------>
      <h4 class="header"> The <mark>EvalError</mark> object </h4>
      <pre>
    try {
        eval(blaBla);                           <span style="color:orangered;">&lt;-- does not throw any EvalError</span>
    } catch(e) {
        e.name                                  // -> "ReferenceError"      // not an EvalError instance
    }
    </pre>
    </details>
    <hr>
    <!--------------------------------------------------------------------------------------------------------------------------------->
    <h2 class="header"> The <mark>try...catch</mark> statement </h2>
    <p> - the <mark>try...catch</mark> statement is used try to run some code and cach eventual errors in a scope so the main program doesn't exit </p>
    <pre class="syntax">
    try {
        <i>// code to test...</i>
    }
    catch (<strong>err</strong>) {                  // code block executes if an error is thrown in the <mark>try</mark> block
                                                    // <span class="fab fa-js">2019</span> <span id="browserSupport" style="color:yellow;" title="updated : 2025-03-02"><span><i class="fab fa-chrome"></i> 65 </span><span><i class="fab fa-firefox"></i> 58 </span><span><i class="fab fa-opera"></i> 53 </span><span><i class="fab fa-internet-explorer"></i><i class="fab fa-edge"></i> 79 </span><span><i class="fab fa-safari"></i> 11.1 </span><span><i class="fab fa-node-js"></i> 10 </span></span>  // the <mark>(<strong>err</strong>)</mark> is optional
        <i>// error handling here... </i>
    }    
    finally {                                       // garanteed to executed regardless of the result of <mark>try</mark> and <mark>catch</mark> (even if the error is not handled) 
        <i>// finally code... </i> 
    }
    
    
// valid statemenet combinations ---------------------------
    <mark>try...catch</mark>
    <mark>try...finally</mark>
    <mark>try...catch...finally</mark>
    </pre>
    <details class="example">
      <summary> DEMO </summary>
      <pre>
    try {
        bla..bla                                                                       // this throws an error 
    }
    catch (err) {                                                                      // the error is caught and returned here 'err'   
        err;                                                                           // -> ReferenceError 
    }                                                                                  // the "catch" statement block only fires if error is thrown byt the "try" statement
    finally {
        console.log( "garanteed" );                                                    // block is garanteed to fire 
    }                                                                                  // if an error is thrown by the "try" statement and there is not "catch" statement to handle it all further code fails but the "finally" statemenet   
    
    console.log( 'continue' );                                                          // if the thrown error in not caught by the "catch" statement this won't be executed!    
    </pre>
    </details>

    <br><br>
  </body>
</html>